Workbook

Sheet Mode d'emploi
A1: Relecture du vocabulaire coranique
A3: État du fichier
A4: Racines, fréquences et versets d'exemple : vérifiés automatiquement sur le corpus morphologique — fiables.
A5: Traductions françaises : relues une première fois, mais jamais contrôlées par un tiers. C'est l'objet de ce fichier.
A7: Colonnes à remplir — surlignées en jaune dans l'onglet « Mots »
A8: Validé ? → OK / À corriger / Douteux (liste déroulante)
A9: Correction → la traduction française corrigée, si besoin
A10: Remarque → tout commentaire libre
A12: Exemple de ligne remplie
A13: id = rabb | arabe = رَبّ | sens = Seigneur | Validé ? = À corriger | Correction = Seigneur, Maître | Remarque = préciser la nuance d'éducation
A15: Comment lire la colonne « Mots couverts »
A16: Nombre de mots du Coran que l'entrée permet de reconnaître : toute la famille de la racine pour les noms,
... A27: il faut reporter les corrections dans le fichier TypeScript, ou me redonner ce tableau pour que je le fasse.

Sheet Mots
A1: Pack | B1: N° | C1: id | D1: Arabe | E1: Translittération | F1: Sens (FR) | G1: Précision | H1: Racine | I1: Nature | J1: Mots couverts | K1: Sourate | L1: Verset | M1: Validé ? | N1: Correction | O1: Remarque
A2: Les mots de la Fâtiha | B2: 1 | C2: ism | D2: اِسْم | E2: ism | F2: nom | H2: س م و | I2: nom | J2: 381 | K2: 1 | L2: 1
A3: Les mots de la Fâtiha | B3: 1 | C3: allah | D3: اللَّه | E3: Allāh | F3: Allah | G3: Le nom propre de Dieu, jamais traduit ni mis au pluriel. | I3: nomPropre | J3: 2699 | K3: 1 | L3: 1
A4: Les mots de la Fâtiha | B4: 1 | C4: rahman | D4: الرَّحْمَٰن | E4: ar-Raḥmān | F4: le Tout Miséricordieux | G4: Miséricorde immense qui englobe toute la création, croyants et mécréants. | H4: ر ح م | I4: nom | J4: 339 | K4: 1 | L4: 3
A5: Les mots de la Fâtiha | B5: 1 | C5: rahim | D5: الرَّحِيم | E5: ar-Raḥīm | F5: le Très Miséricordieux | G5: Miséricorde constante et particulière, réservée aux croyants dans l'au-delà. | H5: ر ح م | I5: adjectif | J5: 339 | K5: 1 | L5: 3
A6: Les mots de la Fâtiha | B6: 1 | C6: hamd | D6: الْحَمْد | E6: al-ḥamd | F6: la louange | G6: Louange qui contient à la fois l'éloge et la reconnaissance. | H6: ح م د | I6: nom | J6: 68 | K6: 1 | L6: 2
A7: Les mots de la Fâtiha | B7: 1 | C7: rabb | D7: رَبّ | E7: rabb | F7: Seigneur | G7: Celui qui crée, possède, éduque et pourvoit. | H7: ر ب ب | I7: nom | J7: 980 | K7: 1 | L7: 2
A8: Les mots de la Fâtiha | B8: 1 | C8: alamin | D8: عَالَمِين | E8: ʿālamīn | F8: les mondes, les univers | H8: ع ل م | I8: nom | J8: 854 | K8: 1 | L8: 2
A9: Les mots de la Fâtiha | B9: 1 | C9: malik | D9: مَالِك | E9: mālik | F9: Maître, Souverain | H9: م ل ك | I9: nom | J9: 206 | K9: 1 | L9: 4
A10: Les mots de la Fâtiha | B10: 1 | C10: yawm | D10: يَوْم | E10: yawm | F10: jour | H10: ي و م | I10: nom | J10: 475 | K10: 1 | L10: 4
A11: Les mots de la Fâtiha | B11: 1 | C11: din | D11: دِين | E11: dīn | F11: religion, rétribution | G11: Dans « yawm ad-dīn », le sens est celui du Jugement, de la rétribution. | H11: د ي ن | I11: nom | J11: 101 | K11: 1 | L11: 4
A12: Les mots de la Fâtiha | B12: 1 | C12: abada | D12: عَبَدَ | E12: ʿabada | F12: adorer | G12: Même racine que ʿabd, le serviteur. | H12: ع ب د | I12: verbe | J12: 275 | K12: 1 | L12: 5
A13: Les mots de la Fâtiha | B13: 1 | C13: istaana | D13: اِسْتَعَانَ | E13: istaʿāna | F13: demander secours | H13: ع و ن | I13: verbe | J13: 12 | K13: 1 | L13: 5
A14: Les mots de la Fâtiha | B14: 1 | C14: hada | D14: هَدَىٰ | E14: hadā | F14: guider | H14: ه د ي | I14: verbe | J14: 316 | K14: 1 | L14: 6
A15: Les mots de la Fâtiha | B15: 1 | C15: sirat | D15: صِرَاط | E15: ṣirāṭ | F15: chemin, voie | G15: Une voie large et droite, par opposition au sentier étroit. | H15: ص ر ط | I15: nom | J15: 45 | K15: 1 | L15: 6
A16: Les mots de la Fâtiha | B16: 1 | C16: mustaqim | D16: مُسْتَقِيم | E16: mustaqīm | F16: droit, rectiligne | H16: ق و م | I16: adjectif | J16: 660 | K16: 1 | L16: 6
A17: Allah et Ses noms | B17: 2 | C17: ilah | D17: إِلَٰه | E17: ilāh | F17: divinité | G17: Nom commun : ce qui est adoré. À distinguer d'Allah, nom propre. | H17: أ ل ه | I17: nom | J17: 2851 | K17: 2 | L17: 163
A18: Allah et Ses noms | B18: 2 | C18: rahma | D18: رَحْمَة | E18: raḥma | F18: miséricorde | H18: ر ح م | I18: nom | J18: 339 | K18: 7 | L18: 156
A19: Allah et Ses noms | B19: 2 | C19: alim | D19: عَلِيم | E19: ʿalīm | F19: Omniscient | H19: ع ل م | I19: adjectif | J19: 854 | K19: 2 | L19: 32
A20: Allah et Ses noms | B20: 2 | C20: hakim | D20: حَكِيم | E20: ḥakīm | F20: Sage | H20: ح ك م | I20: adjectif | J20: 210 | K20: 2 | L20: 32
A21: Allah et Ses noms | B21: 2 | C21: aziz | D21: عَزِيز | E21: ʿazīz | F21: Puissant, Inaccessible | H21: ع ز ز | I21: adjectif | J21: 120 | K21: 2 | L21: 129
A22: Allah et Ses noms | B22: 2 | C22: ghafur | D22: غَفُور | E22: ghafūr | F22: Pardonneur | H22: غ ف ر | I22: adjectif | J22: 234 | K22: 2 | L22: 173
A23: Allah et Ses noms | B23: 2 | C23: sami | D23: سَمِيع | E23: samīʿ | F23: Audient, qui entend tout | H23: س م ع | I23: adjectif | J23: 185 | K23: 2 | L23: 127
A24: Allah et Ses noms | B24: 2 | C24: basir | D24: بَصِير | E24: baṣīr | F24: Clairvoyant, qui voit tout | H24: ب ص ر | I24: adjectif | J24: 148 | K24: 2 | L24: 96
A25: Allah et Ses noms | B25: 2 | C25: qadir | D25: قَدِير | E25: qadīr | F25: Omnipotent | H25: ق د ر | I25: adjectif | J25: 132 | K25: 2 | L25: 20
A26: Allah et Ses noms | B26: 2 | C26: khabir | D26: خَبِير | E26: khabīr | F26: Parfaitement Informé | H26: خ ب ر | I26: adjectif | J26: 52 | K26: 2 | L26: 234
A27: Allah et Ses noms | B27: 2 | C27: karim | D27: كَرِيم | E27: karīm | F27: Noble, Généreux | H27: ك ر م | I27: adjectif | J27: 47 | K27: 27 | L27: 40
A28: Allah et Ses noms | B28: 2 | C28: azim | D28: عَظِيم | E28: ʿaẓīm | F28: Immense, Grandiose | H28: ع ظ م | I28: adjectif | J28: 128 | K28: 2 | L28: 255
A29: Allah et Ses noms | B29: 2 | C29: halim | D29: حَلِيم | E29: ḥalīm | F29: Longanime, plein de mansuétude | H29: ح ل م | I29: adjectif | J29: 21 | K29: 2 | L29: 225
... A35: Allah et Ses noms | B35: 2 | C35: nur | D35: نُور | E35: nūr | F35: lumière | H35: ن و ر | I35: nom | J35: 194 | K35: 24 | L35: 35
A36: Les mots-outils essentiels | B36: 3 | C36: min | D36: مِنْ | E36: min | F36: de, depuis, parmi | I36: particule | J36: 4083 | K36: 2 | L36: 3
A37: Les mots-outils essentiels | B37: 3 | C37: ila | D37: إِلَىٰ | E37: ilā | F37: vers, jusqu'à | I37: particule | J37: 742 | K37: 2 | L37: 14
A38: Les mots-outils essentiels | B38: 3 | C38: ala | D38: عَلَىٰ | E38: ʿalā | F38: sur, contre | I38: particule | J38: 1458 | K38: 2 | L38: 5
A39: Les mots-outils essentiels | B39: 3 | C39: fi | D39: فِي | E39: fī | F39: dans, en | I39: particule | J39: 1701 | K39: 2 | L39: 10
A40: Les mots-outils essentiels | B40: 3 | C40: an | D40: عَنْ | E40: ʿan | F40: au sujet de, loin de | I40: particule | J40: 468 | K40: 2 | L40: 189
A41: Les mots-outils essentiels | B41: 3 | C41: maa | D41: مَعَ | E41: maʿa | F41: avec | I41: particule | J41: 164 | K41: 2 | L41: 153
A42: Les mots-outils essentiels | B42: 3 | C42: bayna | D42: بَيْنَ | E42: bayna | F42: entre | H42: ب ي ن | I42: particule | J42: 523 | K42: 2 | L42: 66
A43: Les mots-outils essentiels | B43: 3 | C43: inda | D43: عِنْدَ | E43: ʿinda | F43: auprès de, chez | I43: particule | J43: 197 | K43: 2 | L43: 54
A44: Les mots-outils essentiels | B44: 3 | C44: baada | D44: بَعْدَ | E44: baʿda | F44: après | H44: ب ع د | I44: particule | J44: 235 | K44: 2 | L44: 27
A45: Les mots-outils essentiels | B45: 3 | C45: qabla | D45: قَبْلَ | E45: qabla | F45: avant | H45: ق ب ل | I45: particule | J45: 294 | K45: 2 | L45: 25
...

Sheet Synthèse
A1: Avancement de la relecture
A3: Total de mots | B3: =COUNTA(Mots!C2:C368) -> 367
A4: Relus | B4: =COUNTA(Mots!M2:M368) -> 0
A5: Restants | B5: =B3-B4 -> 367
A6: Avancement | B6: =IF(B3=0,0,B4/B3) -> 0
A8: OK | B8: =COUNTIF(Mots!M2:M368,"OK") -> 0
A9: À corriger | B9: =COUNTIF(Mots!M2:M368,"À corriger") -> 0
A10: Douteux | B10: =COUNTIF(Mots!M2:M368,"Douteux") -> 0
A11: Avec précision | B11: =COUNTA(Mots!G2:G368) -> 82
A13: Rentabilité par pack — total des mots du Coran couverts
A14: Pack | B14: Mots | C14: Relus | D14: Mots couverts
A15: Les mots de la Fâtiha | B15: =COUNTIF(Mots!$A$2:$A$368,A15) -> 15 | C15: =COUNTIFS(Mots!$A$2:$A$368,A15,Mots!$M$2:$M$368,"<>") -> 0 | D15: =SUMIF(Mots!$A$2:$A$368,A15,Mots!$J$2:$J$368) -> 7750
A16: Allah et Ses noms | B16: =COUNTIF(Mots!$A$2:$A$368,A16) -> 19 | C16: =COUNTIFS(Mots!$A$2:$A$368,A16,Mots!$M$2:$M$368,"<>") -> 0 | D16: =SUMIF(Mots!$A$2:$A$368,A16,Mots!$J$2:$J$368) -> 6594
A17: Les mots-outils essentiels | B17: =COUNTIF(Mots!$A$2:$A$368,A17) -> 19 | C17: =COUNTIFS(Mots!$A$2:$A$368,A17,Mots!$M$2:$M$368,"<>") -> 0 | D17: =SUMIF(Mots!$A$2:$A$368,A17,Mots!$J$2:$J$368) -> 11317
A18: Les grands verbes | B18: =COUNTIF(Mots!$A$2:$A$368,A18) -> 23 | C18: =COUNTIFS(Mots!$A$2:$A$368,A18,Mots!$M$2:$M$368,"<>") -> 0 | D18: =SUMIF(Mots!$A$2:$A$368,A18,Mots!$J$2:$J$368) -> 8435
A19: La foi et la mécréance | B19: =COUNTIF(Mots!$A$2:$A$368,A19) -> 19 | C19: =COUNTIFS(Mots!$A$2:$A$368,A19,Mots!$M$2:$M$368,"<>") -> 0 | D19: =SUMIF(Mots!$A$2:$A$368,A19,Mots!$J$2:$J$368) -> 6068
A20: Le Livre et la révélation | B20: =COUNTIF(Mots!$A$2:$A$368,A20) -> 17 | C20: =COUNTIFS(Mots!$A$2:$A$368,A20,Mots!$M$2:$M$368,"<>") -> 0 | D20: =SUMIF(Mots!$A$2:$A$368,A20,Mots!$J$2:$J$368) -> 4573
A21: Pronoms et démonstratifs | B21: =COUNTIF(Mots!$A$2:$A$368,A21) -> 18 | C21: =COUNTIFS(Mots!$A$2:$A$368,A21,Mots!$M$2:$M$368,"<>") -> 0 | D21: =SUMIF(Mots!$A$2:$A$368,A21,Mots!$J$2:$J$368) -> 11192
A22: L'au-delà : Paradis et Enfer | B22: =COUNTIF(Mots!$A$2:$A$368,A22) -> 21 | C22: =COUNTIFS(Mots!$A$2:$A$368,A22,Mots!$M$2:$M$368,"<>") -> 0 | D22: =SUMIF(Mots!$A$2:$A$368,A22,Mots!$J$2:$J$368) -> 3540
A23: Le ciel, la terre et la création | B23: =COUNTIF(Mots!$A$2:$A$368,A23) -> 20 | C23: =COUNTIFS(Mots!$A$2:$A$368,A23,Mots!$M$2:$M$368,"<>") -> 0 | D23: =SUMIF(Mots!$A$2:$A$368,A23,Mots!$J$2:$J$368) -> 2126
A24: Négations, conditions et liaisons | B24: =COUNTIF(Mots!$A$2:$A$368,A24) -> 19 | C24: =COUNTIFS(Mots!$A$2:$A$368,A24,Mots!$M$2:$M$368,"<>") -> 0 | D24: =SUMIF(Mots!$A$2:$A$368,A24,Mots!$J$2:$J$368) -> 14995
A25: L'homme : corps et âme | B25: =COUNTIF(Mots!$A$2:$A$368,A25) -> 16 | C25: =COUNTIFS(Mots!$A$2:$A$368,A25,Mots!$M$2:$M$368,"<>") -> 0 | D25: =SUMIF(Mots!$A$2:$A$368,A25,Mots!$J$2:$J$368) -> 1429
A26: Le bien, le mal et la piété | B26: =COUNTIF(Mots!$A$2:$A$368,A26) -> 21 | C26: =COUNTIFS(Mots!$A$2:$A$368,A26,Mots!$M$2:$M$368,"<>") -> 0 | D26: =SUMIF(Mots!$A$2:$A$368,A26,Mots!$J$2:$J$368) -> 3064
... A34: Verbes du récit | B34: =COUNTIF(Mots!$A$2:$A$368,A34) -> 20 | C34: =COUNTIFS(Mots!$A$2:$A$368,A34,Mots!$M$2:$M$368,"<>") -> 0 | D34: =SUMIF(Mots!$A$2:$A$368,A34,Mots!$J$2:$J$368) -> 1575
A36: Ne pas additionner la colonne « Mots couverts » : deux mots d'une même racine couvrent les mêmes occurrences. Elle sert à classer les packs, pas à totaliser. La couverture réelle est de 76,7 %.
